python main.py read --config secrets/config.json --catalog integration_tests/configured_catalog.json 
{
  "type": "LOG",
  "log": {
    "level": "FATAL",
    "message": "'YYYY-MM-DD' is not of type 'array'

Failed validating 'type' in metaschema['properties']['properties']['additionalProperties']['properties']['examples']:
    {'items': True, 'type': 'array'}

On schema['properties']['start_date']['examples']:
    'YYYY-MM-DD'
Traceback (most recent call last):
  File \"/home/jazzdung/projects/airbyte-connectors/source-tcbs-price-history/main.py\", line 13, in <module>
    launch(source, sys.argv[1:])
  File \"/home/jazzdung/.local/lib/python3.10/site-packages/airbyte_cdk/entrypoint.py\", line 156, in launch
    for message in source_entrypoint.run(parsed_args):
  File \"/home/jazzdung/.local/lib/python3.10/site-packages/airbyte_cdk/entrypoint.py\", line 98, in run
    yield from map(AirbyteEntrypoint.airbyte_message_to_string, self.read(source_spec, config, config_catalog, state))
  File \"/home/jazzdung/.local/lib/python3.10/site-packages/airbyte_cdk/entrypoint.py\", line 130, in read
    self.validate_connection(source_spec, config)
  File \"/home/jazzdung/.local/lib/python3.10/site-packages/airbyte_cdk/entrypoint.py\", line 139, in validate_connection
    check_config_against_spec_or_exit(connector_config, source_spec)
  File \"/home/jazzdung/.local/lib/python3.10/site-packages/airbyte_cdk/sources/utils/schema_helpers.py\", line 159, in check_config_against_spec_or_exit
    validate(instance=config, schema=spec_schema)
  File \"/home/jazzdung/.local/lib/python3.10/site-packages/jsonschema/validators.py\", line 930, in validate
    cls.check_schema(schema)
  File \"/home/jazzdung/.local/lib/python3.10/site-packages/jsonschema/validators.py\", line 294, in check_schema
    raise exceptions.SchemaError.create_from(error)
jsonschema.exceptions.SchemaError: 'YYYY-MM-DD' is not of type 'array'

Failed validating 'type' in metaschema['properties']['properties']['additionalProperties']['properties']['examples']:
    {'items': True, 'type': 'array'}

On schema['properties']['start_date']['examples']:
    'YYYY-MM-DD'"
  }
}
{
  "type": "TRACE",
  "trace": {
    "type": "ERROR",
    "emitted_at": 1687460439466.6792,
    "error": {
      "message": "Something went wrong in the connector. See the logs for more details.",
      "internal_message": "'YYYY-MM-DD' is not of type 'array'

Failed validating 'type' in metaschema['properties']['properties']['additionalProperties']['properties']['examples']:
    {'items': True, 'type': 'array'}

On schema['properties']['start_date']['examples']:
    'YYYY-MM-DD'",
      "stack_trace": "Traceback (most recent call last):
  File \"/home/jazzdung/projects/airbyte-connectors/source-tcbs-price-history/main.py\", line 13, in <module>
    launch(source, sys.argv[1:])
  File \"/home/jazzdung/.local/lib/python3.10/site-packages/airbyte_cdk/entrypoint.py\", line 156, in launch
    for message in source_entrypoint.run(parsed_args):
  File \"/home/jazzdung/.local/lib/python3.10/site-packages/airbyte_cdk/entrypoint.py\", line 98, in run
    yield from map(AirbyteEntrypoint.airbyte_message_to_string, self.read(source_spec, config, config_catalog, state))
  File \"/home/jazzdung/.local/lib/python3.10/site-packages/airbyte_cdk/entrypoint.py\", line 130, in read
    self.validate_connection(source_spec, config)
  File \"/home/jazzdung/.local/lib/python3.10/site-packages/airbyte_cdk/entrypoint.py\", line 139, in validate_connection
    check_config_against_spec_or_exit(connector_config, source_spec)
  File \"/home/jazzdung/.local/lib/python3.10/site-packages/airbyte_cdk/sources/utils/schema_helpers.py\", line 159, in check_config_against_spec_or_exit
    validate(instance=config, schema=spec_schema)
  File \"/home/jazzdung/.local/lib/python3.10/site-packages/jsonschema/validators.py\", line 930, in validate
    cls.check_schema(schema)
  File \"/home/jazzdung/.local/lib/python3.10/site-packages/jsonschema/validators.py\", line 294, in check_schema
    raise exceptions.SchemaError.create_from(error)
jsonschema.exceptions.SchemaError: 'YYYY-MM-DD' is not of type 'array'

Failed validating 'type' in metaschema['properties']['properties']['additionalProperties']['properties']['examples']:
    {'items': True, 'type': 'array'}

On schema['properties']['start_date']['examples']:
    'YYYY-MM-DD'
",
      "failure_type": "system_error"
    }
  }
}